Workbook

Sheet EXECUTIVE DASHBOARD
A1: MASTER SEO MATRIX 2026 — chatbot.thuexemaynguyentu.com
A2: Ngày dữ liệu: 2026-11-01 · Nguồn: repository + HTML build · Search Console: NOT CONNECTED · Mọi giá trị dưới đây là công thức tham chiếu các sheet.
A4: KPI | B4: Giá trị | C4: Công thức / nguồn | D4: Ghi chú
A5: Tổng URL kiểm kê | B5: =COUNTA('URL INVENTORY'!A:A)-1 | C5: URL INVENTORY: COUNTA('URL INVENTORY'!A:A)-1 | D5: Hợp nhất sitemap + build + link graph + manifest
A6: URL trong sitemap | B6: =COUNTIF('URL INVENTORY'!E:E,"Có") | C6: URL INVENTORY: COUNTIF('URL INVENTORY'!E:E,"Có")
A7: URL có file build | B7: =COUNTIF('URL INVENTORY'!F:F,"Có") | C7: URL INVENTORY: COUNTIF('URL INVENTORY'!F:F,"Có")
A8: URL có ≥ 1 trang liên kết vào | B8: =COUNTIF('URL INVENTORY'!G:G,">0") | C8: URL INVENTORY: COUNTIF('URL INVENTORY'!G:G,">0")
A9: URL đối soát OK (≥ 3 nguồn) | B9: =COUNTIF('URL INVENTORY'!K:K,"OK") | C9: URL INVENTORY: COUNTIF('URL INVENTORY'!K:K,"OK")
A10: URL đã kiểm tra HTTP live = 200 | B10: =COUNTIF('URL INVENTORY'!I:I,"200*") | C10: URL INVENTORY: COUNTIF('URL INVENTORY'!I:I,"200*") | D10: Mẫu 2026-10-28/29
A11: Bài viết | B11: =COUNTIF('URL INVENTORY'!C:C,"Bài viết") | C11: URL INVENTORY: COUNTIF('URL INVENTORY'!C:C,"Bài viết")
A12: Phân loại KEEP | B12: =COUNTIF('URL INVENTORY'!L:L,"KEEP") | C12: URL INVENTORY: COUNTIF('URL INVENTORY'!L:L,"KEEP")
A13: Phân loại IMPROVE | B13: =COUNTIF('URL INVENTORY'!L:L,"IMPROVE") | C13: URL INVENTORY: COUNTIF('URL INVENTORY'!L:L,"IMPROVE")
A14: Phân loại EXPAND | B14: =COUNTIF('URL INVENTORY'!L:L,"EXPAND") | C14: URL INVENTORY: COUNTIF('URL INVENTORY'!L:L,"EXPAND")
A15: Phân loại CONSOLIDATE-CANDIDATE | B15: =COUNTIF('URL INVENTORY'!L:L,"CONSOLIDATE-CANDIDATE") | C15: URL INVENTORY: COUNTIF('URL INVENTORY'!L:L,"CONSOLIDATE-CANDIDATE")
A16: Phân loại REDIRECT-CANDIDATE | B16: =COUNTIF('URL INVENTORY'!L:L,"REDIRECT-CANDIDATE") | C16: URL INVENTORY: COUNTIF('URL INVENTORY'!L:L,"REDIRECT-CANDIDATE")
A17: Phân loại NOINDEX-CANDIDATE | B17: =COUNTIF('URL INVENTORY'!L:L,"NOINDEX-CANDIDATE") | C17: URL INVENTORY: COUNTIF('URL INVENTORY'!L:L,"NOINDEX-CANDIDATE")
A18: Nhóm từ khóa NEW CONTENT (đề xuất) | B18: =COUNTIF('KEYWORD GAP'!N:N,"NEW CONTENT*") | C18: KEYWORD GAP: COUNTIF('KEYWORD GAP'!N:N,"NEW CONTENT*") | D18: Owner duyệt
A19: QA proxy trung bình (/100) | B19: =ROUND(AVERAGE('QA RESULTS'!K:K),1) | C19: QA RESULTS: ROUND(AVERAGE('QA RESULTS'!K:K),1) | D19: Proxy tự động
A20: Tỉ lệ URL đạt QA proxy ≥ 85 | B20: =ROUND(COUNTIF('QA RESULTS'!K:K,">=85")/COUNT('QA RESULTS'!K:K),3) | C20: QA RESULTS: ROUND(COUNTIF('QA RESULTS'!K:K,">=85")/COUNT('QA RESULTS'!K:K),3)
A21: QA nhà máy trung bình (bài) | B21: =ROUND(AVERAGE('QA RESULTS'!M:M),1) | C21: QA RESULTS: ROUND(AVERAGE('QA RESULTS'!M:M),1) | D21: tools/article-qa.mjs
A22: Từ khóa trong Keyword Master | B22: =COUNTA('KEYWORD MASTER'!A:A)-2 | C22: KEYWORD MASTER: COUNTA('KEYWORD MASTER'!A:A)-2 | D22: Trừ dòng ghi chú + tiêu đề
A23: Từ khóa có volume đo được | B23: =COUNT('KEYWORD MASTER'!E:E) | C23: KEYWORD MASTER: COUNT('KEYWORD MASTER'!E:E) | D23: Ô N/A không tính
A24: Truy vấn SERP đã chụp (có vị trí #1) | B24: =COUNTIF('COMPETITOR SERP'!C:C,1) | C24: COMPETITOR SERP: COUNTIF('COMPETITOR SERP'!C:C,1)
A25: Lượt website này xuất hiện trong SERP chụp | B25: =COUNTIF('COMPETITOR SERP'!G:G,"website này") | C25: COMPETITOR SERP: COUNTIF('COMPETITOR SERP'!G:G,"website này") | D25: Một thời điểm
A26: Kiểm tra kỹ thuật FAIL | B26: =COUNTIF('TECHNICAL SEO AUDIT'!H:H,"FAIL") | C26: TECHNICAL SEO AUDIT: COUNTIF('TECHNICAL SEO AUDIT'!H:H,"FAIL")
A27: Kiểm tra kỹ thuật WARN | B27: =COUNTIF('TECHNICAL SEO AUDIT'!H:H,"WARN") | C27: TECHNICAL SEO AUDIT: COUNTIF('TECHNICAL SEO AUDIT'!H:H,"WARN")
A28: LCP lab tệ nhất (ms) | B28: =_xlfn.MAXIFS('TECHNICAL SEO AUDIT'!F:F,'TECHNICAL SEO AUDIT'!B:B,"Core Web Vitals (LAB)",'TECHNICAL SEO AUDIT'!C:C,"LCP*") | C28: TECHNICAL SEO AUDIT: _xlfn.MAXIFS('TECHNICAL SEO AUDIT'!F:F,'TECHNICAL SEO AUDIT'!B:B,"Core Web Vitals (LAB)",'TECHNICAL SEO AUDIT'!C:C,"LCP*") | D28: LAB, ngưỡng 2.500
A29: Trang lỗi structured data | B29: =COUNTIF('STRUCTURED DATA'!H:H,"LỖI") | C29: STRUCTURED DATA: COUNTIF('STRUCTURED DATA'!H:H,"LỖI")
A30: Bài có ảnh đại diện LIVE | B30: =COUNTIF('IMAGE SEO'!C:C,"LIVE_VERIFIED") | C30: IMAGE SEO: COUNTIF('IMAGE SEO'!C:C,"LIVE_VERIFIED")
A31: Bài IMAGE PENDING | B31: =COUNTIF('IMAGE SEO'!C:C,"IMAGE PENDING") | C31: IMAGE SEO: COUNTIF('IMAGE SEO'!C:C,"IMAGE PENDING") | D31: Nhà máy ảnh tạm dừng
A32: Trang mồ côi nội dung | B32: =COUNTIF('INTERNAL LINK MATRIX'!M:M,"Có") | C32: INTERNAL LINK MATRIX: COUNTIF('INTERNAL LINK MATRIX'!M:M,"Có")
A33: Vào ngữ cảnh TB / bài | B33: =ROUND(AVERAGEIF('INTERNAL LINK MATRIX'!B:B,"Bài viết",'INTERNAL LINK MATRIX'!E:E),1) | C33: INTERNAL LINK MATRIX: ROUND(AVERAGEIF('INTERNAL LINK MATRIX'!B:B,"Bài viết",'INTERNAL LINK MATRIX'!E:E),1)
A34: Nhóm CONSOLIDATE-CANDIDATE (cannibalization) | B34: =COUNTIF('CANNIBALIZATION'!G:G,"CONSOLIDATE-CANDIDATE") | C34: CANNIBALIZATION: COUNTIF('CANNIBALIZATION'!G:G,"CONSOLIDATE-CANDIDATE")
A35: Backlog chương trình P0 | B35: =COUNTIFS('PRIORITY BACKLOG'!A:A,"Chương trình",'PRIORITY BACKLOG'!C:C,"P0") | C35: PRIORITY BACKLOG: COUNTIFS('PRIORITY BACKLOG'!A:A,"Chương trình",'PRIORITY BACKLOG'!C:C,"P0")
A36: Backlog chương trình P1 | B36: =COUNTIFS('PRIORITY BACKLOG'!A:A,"Chương trình",'PRIORITY BACKLOG'!C:C,"P1") | C36: PRIORITY BACKLOG: COUNTIFS('PRIORITY BACKLOG'!A:A,"Chương trình",'PRIORITY BACKLOG'!C:C,"P1")
A37: Backlog chương trình P2 | B37: =COUNTIFS('PRIORITY BACKLOG'!A:A,"Chương trình",'PRIORITY BACKLOG'!C:C,"P2") | C37: PRIORITY BACKLOG: COUNTIFS('PRIORITY BACKLOG'!A:A,"Chương trình",'PRIORITY BACKLOG'!C:C,"P2")
A38: Backlog chương trình P3 | B38: =COUNTIFS('PRIORITY BACKLOG'!A:A,"Chương trình",'PRIORITY BACKLOG'!C:C,"P3") | C38: PRIORITY BACKLOG: COUNTIFS('PRIORITY BACKLOG'!A:A,"Chương trình",'PRIORITY BACKLOG'!C:C,"P3")
A39: URL còn việc mở (OPEN) | B39: =COUNTIF('URL INVENTORY'!N:N,"OPEN") | C39: URL INVENTORY: COUNTIF('URL INVENTORY'!N:N,"OPEN") | D39: work-queue.csv
A40: URL đã sửa và kiểm tra live (DONE_LIVE) | B40: =COUNTIF('URL INVENTORY'!N:N,"DONE_LIVE") | C40: URL INVENTORY: COUNTIF('URL INVENTORY'!N:N,"DONE_LIVE") | D40: work-status.json
A41: URL đã rà soát, không cần đổi (REVIEWED_OK) | B41: =COUNTIF('URL INVENTORY'!N:N,"REVIEWED_OK") | C41: URL INVENTORY: COUNTIF('URL INVENTORY'!N:N,"REVIEWED_OK") | D41: work-status.json
...

Sheet URL INVENTORY
A1: URL | B1: Article ID | C1: Loại trang | D1: Danh mục | E1: Trong sitemap | F1: Có file build | G1: Số trang liên kết vào (mọi vị trí) | H1: Trong manifest bài | I1: HTTP live (ngày) | J1: Số nguồn xác nhận | K1: Đối soát | L1: Phân loại | M1: Lý do phân loại | N1: Trạng thái công việc | O1: Ưu tiên công việc | P1: Mã việc mở
A2: https://chatbot.thuexemaynguyentu.com/ | B2: N/A | C2: Trang chủ (website) | D2: N/A | E2: Có | F2: Có | G2: 2169 | H2: Không áp dụng | I2: 200 (2026-10-29) | J2: 4 | K2: OK | L2: KEEP | M2: QA proxy ≥ 85, không cờ mở, không cảnh báo nội dung | N2: DONE_LIVE | O2: — | P2: Không
A3: https://chatbot.thuexemaynguyentu.com/agent/ | B3: N/A | C3: Ứng dụng Agent (chat) | D3: N/A | E3: Có | F3: Có | G3: 2168 | H3: Không áp dụng | I3: 200 (2026-10-29) | J3: 3 | K3: OK | L3: KEEP | M3: QA proxy ≥ 85, không cờ mở, không cảnh báo nội dung | N3: REVIEWED_OK | O3: — | P3: Không
A4: https://chatbot.thuexemaynguyentu.com/blog/ | B4: N/A | C4: Blog home | D4: N/A | E4: Có | F4: Có | G4: 2169 | H4: Không áp dụng | I4: 200 (2026-10-28) | J4: 3 | K4: OK | L4: KEEP | M4: QA proxy ≥ 85, không cờ mở, không cảnh báo nội dung | N4: OPEN | O4: P1 | P4: HUB-CONTENT
A5: https://chatbot.thuexemaynguyentu.com/chinh-sach/ | B5: N/A | C5: Trang chính sách thuê xe | D5: N/A | E5: Có | F5: Có | G5: 2169 | H5: Không áp dụng | I5: 200 (2026-10-28) | J5: 4 | K5: OK | L5: KEEP | M5: QA proxy ≥ 85, không cờ mở, không cảnh báo nội dung | N5: OK | O5: — | P5: Không
A6: https://chatbot.thuexemaynguyentu.com/doi-tac/ | B6: N/A | C6: Trang đối tác (B2B) | D6: N/A | E6: Có | F6: Có | G6: 2169 | H6: Không áp dụng | I6: Chưa kiểm tra live trong lô này | J6: 4 | K6: OK | L6: KEEP | M6: QA proxy ≥ 85, không cờ mở, không cảnh báo nội dung | N6: OK | O6: — | P6: Không
A7: https://chatbot.thuexemaynguyentu.com/gia-thue/ | B7: N/A | C7: Trang chuyển đổi (giá) | D7: N/A | E7: Có | F7: Có | G7: 2169 | H7: Không áp dụng | I7: 200 (2026-10-28) | J7: 4 | K7: OK | L7: KEEP | M7: QA proxy ≥ 85, không cờ mở, không cảnh báo nội dung | N7: DONE_LIVE | O7: — | P7: Không
A8: https://chatbot.thuexemaynguyentu.com/gioi-thieu/ | B8: N/A | C8: Trang giới thiệu (E-E-A-T) | D8: N/A | E8: Có | F8: Có | G8: 2169 | H8: Không áp dụng | I8: 200 (2026-10-28) | J8: 4 | K8: OK | L8: KEEP | M8: QA proxy ≥ 85, không cờ mở, không cảnh báo nội dung | N8: OK | O8: — | P8: Không
A9: https://chatbot.thuexemaynguyentu.com/lien-he/ | B9: N/A | C9: Trang chuyển đổi (liên hệ) | D9: N/A | E9: Có | F9: Có | G9: 2169 | H9: Không áp dụng | I9: 200 (2026-10-28) | J9: 4 | K9: OK | L9: KEEP | M9: QA proxy ≥ 85, không cờ mở, không cảnh báo nội dung | N9: DONE_LIVE | O9: — | P9: Không
A10: https://chatbot.thuexemaynguyentu.com/privacy/ | B10: N/A | C10: Pháp lý | D10: N/A | E10: Có | F10: Có | G10: 2169 | H10: Không áp dụng | I10: Chưa kiểm tra live trong lô này | J10: 4 | K10: OK | L10: KEEP | M10: QA proxy ≥ 85, không cờ mở, không cảnh báo nội dung | N10: OK | O10: — | P10: Không
A11: https://chatbot.thuexemaynguyentu.com/terms/ | B11: N/A | C11: Pháp lý | D11: N/A | E11: Có | F11: Có | G11: 2169 | H11: Không áp dụng | I11: Chưa kiểm tra live trong lô này | J11: 4 | K11: OK | L11: KEEP | M11: QA proxy ≥ 85, không cờ mở, không cảnh báo nội dung | N11: OK | O11: — | P11: Không
A12: https://chatbot.thuexemaynguyentu.com/blog/an-toan/ | B12: N/A | C12: Hub danh mục | D12: N/A | E12: Có | F12: Có | G12: 2169 | H12: Không áp dụng | I12: Chưa kiểm tra live trong lô này | J12: 3 | K12: OK | L12: KEEP | M12: QA proxy ≥ 85, không cờ mở, không cảnh báo nội dung | N12: OPEN | O12: P1 | P12: HUB-CONTENT
A13: https://chatbot.thuexemaynguyentu.com/blog/app/ | B13: N/A | C13: Hub danh mục | D13: N/A | E13: Có | F13: Có | G13: 2169 | H13: Không áp dụng | I13: Chưa kiểm tra live trong lô này | J13: 3 | K13: OK | L13: KEEP | M13: QA proxy ≥ 85, không cờ mở, không cảnh báo nội dung | N13: OPEN | O13: P1 | P13: HUB-CONTENT
... A2170: https://chatbot.thuexemaynguyentu.com/blog/xe-dien/pin-xe/page/2/ | B2170: N/A | C2170: Hub chủ đề con (phân trang) | D2170: N/A | E2170: Có | F2170: Có | G2170: 1 | H2170: Không áp dụng | I2170: Chưa kiểm tra live trong lô này | J2170: 3 | K2170: OK | L2170: KEEP | M2170: QA proxy ≥ 85, không cờ mở, không cảnh báo nội dung | N2170: DONE_LIVE | O2170: — | P2170: Không

Sheet KEYWORD MASTER
A1: Nguồn: docs/seo/battle/02-keyword-master-matrix.csv — Volume A: OpenRush research_keywords (Vietnam, Vietnamese, 2026-10-14); Volume B/KD: OpenSEO get_keyword_metrics (DataForSEO, 2026-10-14/2026-10-15) — hai nguồn khác nhau, không gộp. Ô N/A = công cụ không trả số / chưa đo.
A2: Từ khóa | B2: Phạm vi | C2: Cụm | D2: Nhóm engine | E2: Volume A (keyword-demand) | F2: Nguồn A | G2: Volume B (DataForSEO) | H2: KD | I2: Ý định công cụ | J2: Ý định SERP | K2: Tính năng SERP | L2: Vị trí website | M2: Website chị em | N2: Đối thủ #1 | O2: URL tham chiếu | P2: Top 3 | Q2: Độ phủ | R2: Trang đích | S2: Hành động | T2: Điểm ưu tiên | U2: Hạng | V2: Độ tin cậy dữ liệu
A3: xe máy điện vinfast | B3: UNVERIFIED | C3: N/A | D3: N/A | E3: 135000 | F3: OpenRush research_keywords 2026-10-14 | G3: N/A | H3: N/A | I3: transactional | J3: N/A | K3: N/A | L3: N/A | M3: N/A | N3: N/A | O3: N/A | P3: N/A | Q3: N/A | R3: N/A | S3: N/A | T3: 0 | U3: N/A | V3: Đo được (1 công cụ)
A4: thuê xe máy | B4: IN-SCOPE | C4: K02 | D4: thue-xe-may | E4: 33100 | F4: OpenRush research_keywords 2026-10-14 | G4: 33100 | H4: 11 | I4: transactional | J4: Giao dịch – địa phương | K4: local pack | L4: N/A | M4: N/A | N4: alothuexemay.com | O4: https://alothuexemay.com/ | P4: #1 alothuexemay.com; #2 motogo.vn; #3 www.facebook.com | Q4: Đã có bài | R4: /blog/thue-xe/thue-xe-may-gia-re/ | S4: Giữ nguyên | T4: 0 | U4: N/A | V4: Đo được (2 công cụ)
A5: phạt nguội xe máy | B5: IN-SCOPE | C5: K09 | D5: phat-nguoi-xe-may | E5: 27100 | F5: OpenRush research_keywords 2026-10-14 | G5: 27100 | H5: 21 | I5: informational | J5: Hỗn hợp (thương mại + thông tin) | K5: AI Overview, PAA | L5: N/A | M5: N/A | N5: phatnguoi.com.vn | O5: https://phatnguoi.com.vn/ | P5: #1 phatnguoi.com.vn; #2 canhsatgiaothong.bocongan.gov.vn; #3 checkphatnguoi.com.vn | Q5: Đã có bài | R5: /blog/an-toan/den-do-va-camera-phat-nguoi/ | S5: Giữ nguyên | T5: 0 | U5: N/A | V5: Đo được (2 công cụ)
A6: giá xe máy điện vinfast | B6: OUT-INTENT | C6: N/A | D6: N/A | E6: 22200 | F6: OpenRush research_keywords 2026-10-14 | G6: N/A | H6: N/A | I6: commercial | J6: N/A | K6: N/A | L6: N/A | M6: N/A | N6: N/A | O6: N/A | P6: N/A | Q6: N/A | R6: N/A | S6: N/A | T6: 0 | U6: N/A | V6: Đo được (1 công cụ)
A7: phụ tùng xe máy | B7: OUT-INTENT | C7: N/A | D7: N/A | E7: 18100 | F7: OpenRush research_keywords 2026-10-14 | G7: N/A | H7: N/A | I7: transactional | J7: N/A | K7: N/A | L7: N/A | M7: N/A | N7: N/A | O7: N/A | P7: N/A | Q7: N/A | R7: N/A | S7: N/A | T7: 0 | U7: N/A | V7: Đo được (1 công cụ)
A8: sh mode giá | B8: OUT-INTENT | C8: N/A | D8: N/A | E8: 14800 | F8: OpenRush research_keywords 2026-10-14 | G8: N/A | H8: N/A | I8: commercial | J8: N/A | K8: N/A | L8: N/A | M8: N/A | N8: N/A | O8: N/A | P8: N/A | Q8: N/A | R8: N/A | S8: N/A | T8: 0 | U8: N/A | V8: Đo được (1 công cụ)
A9: thi bằng lái xe máy a1 | B9: OUT-INTENT | C9: N/A | D9: N/A | E9: 14800 | F9: OpenRush research_keywords 2026-10-14 | G9: N/A | H9: N/A | I9: informational | J9: N/A | K9: N/A | L9: N/A | M9: N/A | N9: N/A | O9: N/A | P9: N/A | Q9: N/A | R9: N/A | S9: N/A | T9: 0 | U9: N/A | V9: Đo được (1 công cụ)
A10: vinfast xe máy điện | B10: UNVERIFIED | C10: N/A | D10: N/A | E10: 14800 | F10: OpenRush research_keywords 2026-10-14 | G10: N/A | H10: N/A | I10: transactional | J10: N/A | K10: N/A | L10: N/A | M10: N/A | N10: N/A | O10: N/A | P10: N/A | Q10: N/A | R10: N/A | S10: N/A | T10: 0 | U10: N/A | V10: Đo được (1 công cụ)
A11: cửa hàng xe máy | B11: OUT-INTENT | C11: N/A | D11: N/A | E11: 12100 | F11: OpenRush research_keywords 2026-10-14 | G11: N/A | H11: N/A | I11: navigational | J11: N/A | K11: N/A | L11: N/A | M11: N/A | N11: N/A | O11: N/A | P11: N/A | Q11: N/A | R11: N/A | S11: N/A | T11: 0 | U11: N/A | V11: Đo được (1 công cụ)
A12: siêu xe | B12: OUT-INTENT | C12: N/A | D12: N/A | E12: 12100 | F12: OpenRush research_keywords 2026-10-14 | G12: N/A | H12: N/A | I12: informational | J12: N/A | K12: N/A | L12: N/A | M12: N/A | N12: N/A | O12: N/A | P12: N/A | Q12: N/A | R12: N/A | S12: N/A | T12: 0 | U12: N/A | V12: Đo được (1 công cụ)
A13: thi bằng lái xe máy | B13: OUT-INTENT | C13: N/A | D13: N/A | E13: 12100 | F13: OpenRush research_keywords 2026-10-14 | G13: N/A | H13: N/A | I13: informational | J13: N/A | K13: N/A | L13: N/A | M13: N/A | N13: N/A | O13: N/A | P13: N/A | Q13: N/A | R13: N/A | S13: N/A | T13: 0 | U13: N/A | V13: Đo được (1 công cụ)
A14: giá xe honda | B14: OUT-INTENT | C14: N/A | D14: N/A | E14: 9900 | F14: OpenRush research_keywords 2026-10-14 | G14: N/A | H14: N/A | I14: commercial | J14: N/A | K14: N/A | L14: N/A | M14: N/A | N14: N/A | O14: N/A | P14: N/A | Q14: N/A | R14: N/A | S14: N/A | T14: 0 | U14: N/A | V14: Đo được (1 công cụ)
A15: xe máy 50cc | B15: UNVERIFIED | C15: N/A | D15: N/A | E15: 9900 | F15: OpenRush research_keywords 2026-10-14 | G15: N/A | H15: N/A | I15: transactional | J15: N/A | K15: N/A | L15: N/A | M15: N/A | N15: N/A | O15: N/A | P15: N/A | Q15: N/A | R15: N/A | S15: N/A | T15: 0 | U15: N/A | V15: Đo được (1 công cụ)
A16: cho thuê xe máy | B16: IN-SCOPE | C16: K02 | D16: thue-xe-may | E16: 8100 | F16: OpenRush research_keywords 2026-10-14 | G16: 8100 | H16: 0 | I16: commercial | J16: N/A | K16: N/A | L16: N/A | M16: N/A | N16: N/A | O16: N/A | P16: N/A | Q16: Đã có bài | R16: /blog/thue-xe/thue-xe-may-gia-re/ | S16: Giữ nguyên | T16: 0 | U16: N/A | V16: Đo được (2 công cụ)
A17: thuê xe máy đà lạt | B17: OUT-MARKET | C17: N/A | D17: N/A | E17: 8100 | F17: OpenRush research_keywords 2026-10-14 | G17: N/A | H17: N/A | I17: commercial | J17: N/A | K17: N/A | L17: N/A | M17: N/A | N17: N/A | O17: N/A | P17: N/A | Q17: N/A | R17: N/A | S17: N/A | T17: 0 | U17: N/A | V17: Đo được (1 công cụ)
A18: thuê xe máy hà nội | B18: SISTER | C18: LANDSCAPE | D18: N/A | E18: 8100 | F18: OpenRush research_keywords 2026-10-14 | G18: N/A | H18: N/A | I18: commercial | J18: Giao dịch – địa phương | K18: AI Overview, local pack | L18: N/A | M18: N/A | N18: motogo.vn | O18: https://motogo.vn/ha-noi/ | P18: #1 motogo.vn; #2 www.facebook.com; #3 hanoibiker.com | Q18: N/A | R18: N/A | S18: N/A | T18: 0 | U18: N/A | V18: Đo được (1 công cụ)
A19: bằng lái xe máy | B19: IN-SCOPE | C19: K09 | D19: bang-lai-xe-may | E19: 6600 | F19: OpenRush research_keywords 2026-10-14 | G19: 6600 | H19: 0 | I19: informational | J19: Giao dịch – địa phương | K19: AI Overview, local pack | L19: N/A | M19: N/A | N19: hoclaixeotohcm.com | O19: https://hoclaixeotohcm.com/150-cau-hoi-thi-bang-lai-xe-may | P19: #1 hoclaixeotohcm.com; #2 www.thibanglaixemaysaigon.com; #3 tinhte.vn | Q19: Đã có bài | R19: /blog/thue-xe/bang-lai-a1-va-thue-xe-may/ | S19: Giữ nguyên | T19: 0 | U19: N/A | V19: Đo được (2 công cụ)
A20: bánh xe | B20: OUT-INTENT | C20: N/A | D20: N/A | E20: 6600 | F20: OpenRush research_keywords 2026-10-14 | G20: N/A | H20: N/A | I20: informational | J20: N/A | K20: N/A | L20: N/A | M20: N/A | N20: N/A | O20: N/A | P20: N/A | Q20: N/A | R20: N/A | S20: N/A | T20: 0 | U20: N/A | V20: Đo được (1 công cụ)
A21: dấu hiệu xe máy cần thay nhớt | B21: OUT-INTENT | C21: N/A | D21: N/A | E21: 6600 | F21: OpenRush research_keywords 2026-10-14 | G21: N/A | H21: N/A | I21: informational | J21: N/A | K21: N/A | L21: N/A | M21: N/A | N21: N/A | O21: N/A | P21: N/A | Q21: N/A | R21: N/A | S21: N/A | T21: 0 | U21: N/A | V21: Đo được (1 công cụ)
A22: định vị xe máy | B22: OUT-INTENT | C22: N/A | D22: N/A | E22: 6600 | F22: OpenRush research_keywords 2026-10-14 | G22: N/A | H22: N/A | I22: navigational | J22: N/A | K22: N/A | L22: N/A | M22: N/A | N22: N/A | O22: N/A | P22: N/A | Q22: N/A | R22: N/A | S22: N/A | T22: 0 | U22: N/A | V22: Đo được (1 công cụ)
A23: giá xe máy honda | B23: OUT-INTENT | C23: N/A | D23: N/A | E23: 6600 | F23: OpenRush research_keywords 2026-10-14 | G23: N/A | H23: N/A | I23: transactional | J23: N/A | K23: N/A | L23: N/A | M23: N/A | N23: N/A | O23: N/A | P23: N/A | Q23: N/A | R23: N/A | S23: N/A | T23: 0 | U23: N/A | V23: Đo được (1 công cụ)
A24: không bằng lái xe máy phạt bao nhiêu | B24: IN-SCOPE | C24: K09 | D24: khong-bang-lai-xe-may-phat-bao-nhieu | E24: 6600 | F24: OpenRush research_keywords 2026-10-14 | G24: 6600 | H24: 0 | I24: informational | J24: N/A | K24: N/A | L24: N/A | M24: N/A | N24: N/A | O24: N/A | P24: N/A | Q24: Đã có bài | R24: /blog/an-toan/di-xe-khong-giay-phep/ | S24: Giữ nguyên | T24: 0 | U24: N/A | V24: Đo được (2 công cụ)
A25: sửa chữa xe máy | B25: OUT-INTENT | C25: N/A | D25: N/A | E25: 6600 | F25: OpenRush research_keywords 2026-10-14 | G25: N/A | H25: N/A | I25: commercial | J25: N/A | K25: N/A | L25: N/A | M25: N/A | N25: N/A | O25: N/A | P25: N/A | Q25: N/A | R25: N/A | S25: N/A | T25: 0 | U25: N/A | V25: Đo được (1 công cụ)
A26: thuê xe máy đà nẵng | B26: OUT-MARKET | C26: N/A | D26: N/A | E26: 6600 | F26: OpenRush research_keywords 2026-10-14 | G26: N/A | H26: N/A | I26: commercial | J26: N/A | K26: N/A | L26: N/A | M26: N/A | N26: N/A | O26: N/A | P26: N/A | Q26: N/A | R26: N/A | S26: N/A | T26: 0 | U26: N/A | V26: Đo được (1 công cụ)
A27: thuê xe máy nha trang | B27: OUT-MARKET | C27: N/A | D27: N/A | E27: 6600 | F27: OpenRush research_keywords 2026-10-14 | G27: N/A | H27: N/A | I27: transactional | J27: N/A | K27: N/A | L27: N/A | M27: N/A | N27: N/A | O27: N/A | P27: N/A | Q27: N/A | R27: N/A | S27: N/A | T27: 0 | U27: N/A | V27: Đo được (1 công cụ)
A28: xe đạp martin | B28: OUT-INTENT | C28: N/A | D28: N/A | E28: 6600 | F28: OpenRush research_keywords 2026-10-14 | G28: N/A | H28: N/A | I28: transactional | J28: N/A | K28: N/A | L28: N/A | M28: N/A | N28: N/A | O28: N/A | P28: N/A | Q28: N/A | R28: N/A | S28: N/A | T28: 0 | U28: N/A | V28: Đo được (1 công cụ)
A29: xe máy yamaha | B29: OUT-INTENT | C29: N/A | D29: N/A | E29: 6600 | F29: OpenRush research_keywords 2026-10-14 | G29: N/A | H29: N/A | I29: transactional | J29: N/A | K29: N/A | L29: N/A | M29: N/A | N29: N/A | O29: N/A | P29: N/A | Q29: N/A | R29: N/A | S29: N/A | T29: 0 | U29: N/A | V29: Đo được (1 công cụ)
A30: bánh xe đẩy | B30: OUT-INTENT | C30: N/A | D30: N/A | E30: 5400 | F30: OpenRush research_keywords 2026-10-14 | G30: N/A | H30: N/A | I30: transactional | J30: N/A | K30: N/A | L30: N/A | M30: N/A | N30: N/A | O30: N/A | P30: N/A | Q30: N/A | R30: N/A | S30: N/A | T30: 0 | U30: N/A | V30: Đo được (1 công cụ)
A31: giá xe ab 125 | B31: OUT-INTENT | C31: N/A | D31: N/A | E31: 5400 | F31: OpenRush research_keywords 2026-10-14 | G31: N/A | H31: N/A | I31: transactional | J31: N/A | K31: N/A | L31: N/A | M31: N/A | N31: N/A | O31: N/A | P31: N/A | Q31: N/A | R31: N/A | S31: N/A | T31: 0 | U31: N/A | V31: Đo được (1 công cụ)
A32: k có bằng lái xe máy phạt bao nhiêu | B32: IN-SCOPE | C32: K09 | D32: khong-bang-lai-xe-may-phat-bao-nhieu | E32: 5400 | F32: OpenRush research_keywords 2026-10-14 | G32: 5400 | H32: 0 | I32: commercial | J32: N/A | K32: N/A | L32: N/A | M32: N/A | N32: N/A | O32: N/A | P32: N/A | Q32: Đã có bài | R32: /blog/an-toan/di-xe-khong-giay-phep/ | S32: Giữ nguyên | T32: 0 | U32: N/A | V32: Đo được (2 công cụ)
A33: không có bằng lái xe máy phạt bao nhiêu | B33: IN-SCOPE | C33: K09 | D33: khong-bang-lai-xe-may-phat-bao-nhieu | E33: 5400 | F33: OpenRush research_keywords 2026-10-14 | G33: 5400 | H33: 0 | I33: informational | J33: Thông tin | K33: AI Overview | L33: N/A | M33: N/A | N33: www.greensm.com | O33: https://www.greensm.com/vn-vi/news/khong-bang-lai-xe-may-phat-bao-nhieu-khi-cong-an-kiem-tra | P33: #1 www.greensm.com; #2 baomoi.com; #3 osakar.com.vn | Q33: Đã có bài | R33: /blog/an-toan/di-xe-khong-giay-phep/ | S33: Giữ nguyên | T33: 0 | U33: N/A | V33: Đo được (2 công cụ)
A34: mức phạt nồng độ cồn xe máy | B34: IN-SCOPE | C34: K09 | D34: muc-phat-nong-do-con-xe-may | E34: 5400 | F34: OpenRush research_keywords 2026-10-14 | G34: 5400 | H34: 0 | I34: informational | J34: Thông tin | K34: AI Overview | L34: N/A | M34: N/A | N34: teracolongbien.com | O34: https://teracolongbien.com/nong-do-con-phat-bao-nhieu | P34: #1 teracolongbien.com; #2 thuvienphapluat.vn; #3 thuvienphapluat.vn | Q34: Đã có bài | R34: /blog/an-toan/nong-do-con-khi-lai-xe/ | S34: Giữ nguyên | T34: 0 | U34: N/A | V34: Đo được (2 công cụ)
A35: thuê xe máy sài gòn | B35: OUT-MARKET | C35: N/A | D35: N/A | E35: 5400 | F35: OpenRush research_keywords 2026-10-14 | G35: N/A | H35: N/A | I35: commercial | J35: N/A | K35: N/A | L35: N/A | M35: N/A | N35: N/A | O35: N/A | P35: N/A | Q35: N/A | R35: N/A | S35: N/A | T35: 0 | U35: N/A | V35: Đo được (1 công cụ)
A36: vinfast xe máy | B36: UNVERIFIED | C36: N/A | D36: N/A | E36: 5400 | F36: OpenRush research_keywords 2026-10-14 | G36: N/A | H36: N/A | I36: transactional | J36: N/A | K36: N/A | L36: N/A | M36: N/A | N36: N/A | O36: N/A | P36: N/A | Q36: N/A | R36: N/A | S36: N/A | T36: 0 | U36: N/A | V36: Đo được (1 công cụ)
A37: xe điện 3 bánh | B37: OUT-INTENT | C37: N/A | D37: N/A | E37: 5400 | F37: OpenRush research_keywords 2026-10-14 | G37: N/A | H37: N/A | I37: transactional | J37: N/A | K37: N/A | L37: N/A | M37: N/A | N37: N/A | O37: N/A | P37: N/A | Q37: N/A | R37: N/A | S37: N/A | T37: 0 | U37: N/A | V37: Đo được (1 công cụ)
A38: xe điện xmen | B38: OUT-INTENT | C38: N/A | D38: N/A | E38: 5400 | F38: OpenRush research_keywords 2026-10-14 | G38: N/A | H38: N/A | I38: transactional | J38: N/A | K38: N/A | L38: N/A | M38: N/A | N38: N/A | O38: N/A | P38: N/A | Q38: N/A | R38: N/A | S38: N/A | T38: 0 | U38: N/A | V38: Đo được (1 công cụ)
A39: cách sử dụng máy tính thi bằng lái xe a1 | B39: OUT-INTENT | C39: N/A | D39: N/A | E39: 4400 | F39: OpenRush research_keywords 2026-10-14 | G39: N/A | H39: N/A | I39: informational | J39: N/A | K39: N/A | L39: N/A | M39: N/A | N39: N/A | O39: N/A | P39: N/A | Q39: N/A | R39: N/A | S39: N/A | T39: 0 | U39: N/A | V39: Đo được (1 công cụ)
A40: cho thuê xe máy 88 vũng tàu | B40: OUT-INTENT | C40: N/A | D40: N/A | E40: 4400 | F40: OpenRush research_keywords 2026-10-14 | G40: N/A | H40: N/A | I40: transactional | J40: N/A | K40: N/A | L40: N/A | M40: N/A | N40: N/A | O40: N/A | P40: N/A | Q40: N/A | R40: N/A | S40: N/A | T40: 0 | U40: N/A | V40: Đo được (1 công cụ)
...

Sheet KEYWORD GAP
A1: Nguồn: docs/seo/battle/04-opportunity-matrix.csv (engine 06 + SERP 2026-10-14). NEW CONTENT chỉ là đề xuất: chủ sở hữu thêm ID vào content-matrix.csv.
A2: Từ khóa | B2: Nhóm | C2: Volume (đo được) | D2: Cụm | E2: Ý định | F2: Độ phủ | G2: Cạnh tranh SERP | H2: Đối thủ mạnh top 10 | I2: Điểm cơ hội | J2: Loại trang | K2: Hành động engine | L2: Trang đích | M2: Quyết định engine | N2: Phân loại M1
A3: bao nhiêu tuổi được đi xe máy điện | B3: bao-nhieu-tuoi-duoc-di-xe-may-dien | C3: 3080 | D3: K09 | E3: Thông tin | F3: Phủ một phần | G3: Trung bình | H3: vinfastauto.com thuvienphapluat.vn | I3: 4096 | J3: Mục/FAQ trong bài hiện có | K3: Bổ sung mục/FAQ vào bài đích (review body) | L3: /blog/an-toan/xe-may-dien-co-can-bang-lai-khong/ | M3: done | N3: EXPAND
A4: lỗi sử dụng điện thoại khi đi xe máy | B4: loi-su-dung-dien-thoai-khi-di-xe-may | C4: 480 | D4: K10 | E4: Thông tin | F4: Phủ một phần | G4: Trung bình | H4: laodong.vn thuvienphapluat.vn | I4: 491 | J4: Mục/FAQ trong bài hiện có | K4: Bổ sung mục/FAQ vào bài đích (review body) | L4: /blog/an-toan/dien-thoai-khi-lai-xe-tom-tat/ | M4: deferred | N4: EXPAND
A5: bằng lái xe máy là hạng gì | B5: bang-lai-xe-may-la-hang-gi | C5: 1270 | D5: K09 | E5: Hỗn hợp (thương mại + thông tin) | F5: Đã có bài | G5: Trung bình | H5: vinfastauto.com thuvienphapluat.vn | I5: 334 | J5: Title/meta của bài hiện có | K5: Đưa cụm từ chính vào title/meta (article-meta) | L5: /blog/an-toan/cac-loai-bang-lai-xe-may/ | M5: done | N5: COVERED
A6: phượt hà giang bằng xe máy | B6: phuot-ha-giang-bang-xe-may | C6: 70 | D6: K17 | E6: Thông tin (công cụ) | F6: Phủ một phần | G6: Chưa chụp SERP | H6: N/A | I6: 39 | J6: Mục/FAQ trong bài hiện có | K6: Bổ sung mục/FAQ vào bài đích (review body) | L6: /blog/dia-phuong/ha-giang-vong-cung/ | M6: rejected | N6: EXPAND
A7: phượt tam đảo bằng xe máy | B7: phuot-tam-dao-bang-xe-may | C7: 70 | D7: K17 | E7: Thông tin (công cụ) | F7: Phủ một phần | G7: Chưa chụp SERP | H7: N/A | I7: 39 | J7: Mục/FAQ trong bài hiện có | K7: Bổ sung mục/FAQ vào bài đích (review body) | L7: /blog/dia-phuong/tam-dao-bang-xe-may/ | M7: rejected | N7: EXPAND
A8: đường đi thái nguyên từ hà nội bằng xe máy | B8: duong-di-thai-nguyen-tu-ha-noi-bang-xe-may | C8: 30 | D8: K18 | E8: Thông tin (công cụ) | F8: Chưa có | G8: Chưa chụp SERP | H8: N/A | I8: 2 | J8: Giữ trang hiện có | K8: Theo dõi (nhu cầu thấp/chưa đo) | L8: N/A | M8: open | N8: NEW CONTENT
A9: xe máy đi phượt tốt nhất | B9: xe-may-di-phuot-tot-nhat | C9: 30 | D9: K04 | E9: Thương mại (công cụ) | F9: Phủ một phần | G9: Chưa chụp SERP | H9: N/A | I9: 2 | J9: Giữ trang hiện có | K9: Theo dõi (nhu cầu thấp/chưa đo) | L9: /blog/huong-dan/di-phuot-bang-xe-may/ | M9: open | N9: EXPAND
A10: đường đi hà nội hải phòng bằng xe máy | B10: duong-di-ha-noi-hai-phong-bang-xe-may | C10: 20 | D10: K18 | E10: Thông tin (công cụ) | F10: Chưa có | G10: Chưa chụp SERP | H10: N/A | I10: 2 | J10: Giữ trang hiện có | K10: Theo dõi (nhu cầu thấp/chưa đo) | L10: N/A | M10: open | N10: NEW CONTENT
A11: đường đi nam định hà nội bằng xe máy | B11: duong-di-nam-dinh-ha-noi-bang-xe-may | C11: 20 | D11: K18 | E11: Thông tin (công cụ) | F11: Phủ một phần | G11: Chưa chụp SERP | H11: N/A | I11: 2 | J11: Giữ trang hiện có | K11: Theo dõi (nhu cầu thấp/chưa đo) | L11: /blog/dia-phuong/sai-gon-duong-nam/ | M11: open | N11: EXPAND
A12: hội phượt xe máy | B12: hoi-phuot-xe-may | C12: 20 | D12: K04 | E12: Thông tin (công cụ) | F12: Chưa có | G12: Chưa chụp SERP | H12: N/A | I12: 2 | J12: Giữ trang hiện có | K12: Theo dõi (nhu cầu thấp/chưa đo) | L12: N/A | M12: open | N12: NEW CONTENT
A13: kinh nghiệm đi phượt bằng xe máy | B13: kinh-nghiem-di-phuot-bang-xe-may | C13: 20 | D13: K07 | E13: Thông tin (công cụ) | F13: Phủ một phần | G13: Chưa chụp SERP | H13: N/A | I13: 2 | J13: Giữ trang hiện có | K13: Theo dõi (nhu cầu thấp/chưa đo) | L13: /blog/thue-xe/thue-honda-air-blade/ | M13: open | N13: EXPAND
A14: kinh nghiệm phượt sapa bằng xe máy | B14: kinh-nghiem-phuot-sapa-bang-xe-may | C14: 20 | D14: K07 | E14: Thông tin (công cụ) | F14: Chưa có | G14: Chưa chụp SERP | H14: N/A | I14: 2 | J14: Giữ trang hiện có | K14: Theo dõi (nhu cầu thấp/chưa đo) | L14: N/A | M14: open | N14: NEW CONTENT
... A96: xe máy đi phượt cho nữ | B96: xe-may-di-phuot-cho-nu | C96: 10 | D96: K04 | E96: Giao dịch (công cụ) | F96: Phủ một phần | G96: Chưa chụp SERP | H96: N/A | I96: 0 | J96: Giữ trang hiện có | K96: Theo dõi (nhu cầu thấp/chưa đo) | L96: /blog/huong-dan/di-phuot-bang-xe-may/ | M96: open | N96: EXPAND
A97: bằng lái a1 a2 khác gì | B97: bang-lai-a1-a2-khac-gi | C97: N/A | D97: K09 | E97: Thông tin | F97: Đã có bài | G97: Thấp | H97: thuvienphapluat.vn | I97: 0 | J97: Giữ trang hiện có | K97: Giữ nguyên | L97: /blog/an-toan/bang-lai-a1-a2-khac-gi/ | M97: open | N97: COVERED
A98: bảo hiểm xe máy thuê | B98: bao-hiem-xe-may-thue | C98: N/A | D98: K11 | E98: Thông tin | F98: Đã có bài | G98: Thấp | H98: N/A | I98: 0 | J98: Giữ trang hiện có | K98: Giữ nguyên | L98: /blog/an-toan/bao-hiem-khi-thue-xe-may/ | M98: open | N98: COVERED
A99: cấm xe máy xăng vành đai 1 | B99: cam-xe-may-xang-vanh-dai-1 | C99: N/A | D99: K20 | E99: Thông tin | F99: Đã có bài | G99: Cao | H99: thuvienphapluat.vn | I99: 0 | J99: Giữ trang hiện có | K99: Giữ nguyên | L99: /blog/an-toan/cam-xe-may-xang-vanh-dai-1/ | M99: done | N99: COVERED
A100: đặt cọc thuê xe máy | B100: dat-coc-thue-xe-may | C100: N/A | D100: K04 | E100: Thông tin | F100: Đã có bài | G100: Cao | H100: motogo.vn vinwonders.com thuvienphapluat.vn www.otosaigon.com | I100: 0 | J100: Giữ trang hiện có | K100: Giữ nguyên | L100: /blog/huong-dan/dat-coc-the-nao/ | M100: open | N100: COVERED
A101: đặt thuê xe máy online | B101: dat-thue-xe-may-online | C101: N/A | D101: K01 | E101: Giao dịch – địa phương | F101: Phủ một phần | G101: Thấp | H101: motogo.vn | I101: 0 | J101: Trang bán hàng / Google Business Profile | K101: Ý định giao dịch – địa phương: trang bán hàng/Google Business Profile, không viết blog | L101: (trang bán hàng / Google Business Profile) | M101: open | N101: EXPAND
A102: đi hồ tây bằng xe máy | B102: di-ho-tay-bang-xe-may | C102: N/A | D102: K14 | E102: Thông tin | F102: Phủ một phần | G102: Trung bình | H102: motogo.vn vinwonders.com | I102: 0 | J102: Giữ trang hiện có | K102: Theo dõi (nhu cầu thấp/chưa đo) | L102: /blog/dia-phuong/hoang-hon-ho-tay/ | M102: open | N102: EXPAND
A103: đi phố cổ hà nội bằng xe máy | B103: di-pho-co-ha-noi-bang-xe-may | C103: N/A | D103: K12 | E103: Hỗn hợp (thương mại + thông tin) | F103: Phủ một phần | G103: Thấp | H103: justfly.vn | I103: 0 | J103: Giữ trang hiện có | K103: Theo dõi (nhu cầu thấp/chưa đo) | L103: /blog/dia-phuong/ca-phe-pho-co/ | M103: open | N103: EXPAND
A104: đi xe máy xuyên việt | B104: di-xe-may-xuyen-viet | C104: N/A | D104: K18 | E104: Thông tin | F104: Đã có bài | G104: Thấp | H104: N/A | I104: 0 | J104: Giữ trang hiện có | K104: Giữ nguyên | L104: /blog/dia-phuong/hue-xuyen-viet/ | M104: open | N104: COVERED
A105: du lịch biển gần hà nội bằng xe máy | B105: du-lich-bien-gan-ha-noi-bang-xe-may | C105: 0 | D105: K12 | E105: Thông tin (công cụ) | F105: Chưa có | G105: Chưa chụp SERP | H105: N/A | I105: 0 | J105: Giữ trang hiện có | K105: Theo dõi (nhu cầu thấp/chưa đo) | L105: N/A | M105: open | N105: NEW CONTENT
A106: đường đi hà nội thái nguyên bằng xe máy | B106: duong-di-ha-noi-thai-nguyen-bang-xe-may | C106: 0 | D106: K17 | E106: Thông tin (công cụ) | F106: Chưa có | G106: Chưa chụp SERP | H106: N/A | I106: 0 | J106: Giữ trang hiện có | K106: Theo dõi (nhu cầu thấp/chưa đo) | L106: N/A | M106: open | N106: NEW CONTENT
A107: kiểm tra xe máy khi thuê | B107: kiem-tra-xe-may-khi-thue | C107: N/A | D107: K05 | E107: Giao dịch – địa phương | F107: Đã có bài | G107: Thấp | H107: N/A | I107: 0 | J107: Giữ trang hiện có | K107: Giữ nguyên | L107: /blog/huong-dan/kiem-tra-xe-khi-nhan/ | M107: open | N107: COVERED
A108: kinh nghiệm lái xe máy ở hà nội | B108: kinh-nghiem-lai-xe-may-o-ha-noi | C108: N/A | D108: K01 | E108: Hỗn hợp (thương mại + thông tin) | F108: Phủ một phần | G108: Thấp | H108: vinfastauto.com | I108: 0 | J108: Giữ trang hiện có | K108: Theo dõi (nhu cầu thấp/chưa đo) | L108: /blog/app/cong-cu-chon-xe-theo-kinh-nghiem-lai/ | M108: open | N108: EXPAND
A109: tai nạn khi đi xe thuê ai chịu trách nhiệm | B109: tai-nan-khi-di-xe-thue-ai-chiu-trach-nhiem | C109: N/A | D109: K11 | E109: Hỗn hợp (thương mại + thông tin) | F109: Đã có bài | G109: Trung bình | H109: thuvienphapluat.vn | I109: 0 | J109: Giữ trang hiện có | K109: Giữ nguyên | L109: /blog/an-toan/trach-nhiem-khi-tai-nan-voi-xe-thue-cho-nguoi-moi/ | M109: open | N109: COVERED
A110: thuê xe máy ba đình | B110: thue-xe-may-ba-dinh | C110: N/A | D110: K13 | E110: Giao dịch – địa phương | F110: Đã có bài | G110: Trung bình | H110: motogo.vn www.otosaigon.com | I110: 0 | J110: Giữ trang hiện có | K110: Giữ nguyên | L110: /blog/dia-phuong/ba-dinh-xe-may-phuong/ | M110: open | N110: COVERED
A111: thuê xe máy cho người nước ngoài | B111: thue-xe-may-cho-nguoi-nuoc-ngoai | C111: N/A | D111: K01 | E111: Hỗn hợp (thương mại + thông tin) | F111: Đã có bài | G111: Trung bình | H111: vexere.com motogo.vn | I111: 0 | J111: Giữ trang hiện có | K111: Giữ nguyên | L111: /blog/app/app-thue-xe-cho-nguoi-nuoc-ngoai/ | M111: open | N111: COVERED
A112: thuê xe máy đi hà giang | B112: thue-xe-may-di-ha-giang | C112: N/A | D112: K17 | E112: Giao dịch – địa phương | F112: Phủ một phần | G112: Thấp | H112: N/A | I112: 0 | J112: Trang bán hàng / Google Business Profile | K112: Ý định giao dịch – địa phương: trang bán hàng/Google Business Profile, không viết blog | L112: (trang bán hàng / Google Business Profile) | M112: open | N112: EXPAND
A113: thuê xe máy đi ninh bình | B113: thue-xe-may-di-ninh-binh | C113: N/A | D113: K17 | E113: Giao dịch – địa phương | F113: Phủ một phần | G113: Thấp | H113: N/A | I113: 0 | J113: Trang bán hàng / Google Business Profile | K113: Ý định giao dịch – địa phương: trang bán hàng/Google Business Profile, không viết blog | L113: (trang bán hàng / Google Business Profile) | M113: open | N113: EXPAND
A114: thuê xe máy long biên | B114: thue-xe-may-long-bien | C114: N/A | D114: K11 | E114: Giao dịch – địa phương | F114: Phủ một phần | G114: Thấp | H114: N/A | I114: 0 | J114: Trang bán hàng / Google Business Profile | K114: Ý định giao dịch – địa phương: trang bán hàng/Google Business Profile, không viết blog | L114: (trang bán hàng / Google Business Profile) | M114: open | N114: EXPAND
A115: thuê xe máy ở ga hà nội | B115: thue-xe-may-o-ga-ha-noi | C115: N/A | D115: K07 | E115: — | F115: Phủ một phần | G115: Chưa chụp SERP | H115: N/A | I115: 0 | J115: Giữ trang hiện có | K115: Theo dõi (nhu cầu thấp/chưa đo) | L115: /blog/thue-xe/thue-xe-ga/ | M115: open | N115: EXPAND
A116: xe điện bờ hồ | B116: xe-dien-bo-ho | C116: N/A | D116: K12 | E116: — | F116: Có mục trong bài | G116: Chưa chụp SERP | H116: N/A | I116: 0 | J116: Giữ trang hiện có | K116: Giữ nguyên | L116: /blog/dia-phuong/du-lich-hoan-kiem-bang-xe-may/ | M116: open | N116: IMPROVE
A117: xe điện đi phố cổ | B117: xe-dien-di-pho-co | C117: N/A | D117: K08 | E117: — | F117: Đã có bài | G117: Chưa chụp SERP | H117: N/A | I117: 0 | J117: Giữ trang hiện có | K117: Giữ nguyên | L117: /blog/xe-dien/xe-dien-trong-pho-cho-khach-du-lich/ | M117: open | N117: COVERED
A118: xe máy bị thủng lốp giữa đường | B118: xe-may-bi-thung-lop-giua-duong | C118: N/A | D118: K08 | E118: Thông tin | F118: Có mục trong bài | G118: Thấp | H118: N/A | I118: 0 | J118: Giữ trang hiện có | K118: Giữ nguyên | L118: /blog/xe-dien/lop-xe-dien/ | M118: open | N118: IMPROVE
A119: xe thuê bị hỏng phải làm sao | B119: xe-thue-bi-hong-phai-lam-sao | C119: N/A | D119: K20 | E119: Hỗn hợp (thương mại + thông tin) | F119: Đã có bài | G119: Thấp | H119: www.otosaigon.com | I119: 0 | J119: Giữ trang hiện có | K119: Giữ nguyên | L119: /blog/huong-dan/sua-xe-nho-khi-dang-thue-cho-nguoi-moi/ | M119: open | N119: COVERED

Sheet COMPETITOR SERP
A1: Nguồn: data/seo/serp-snapshots/2026-10-14.json (Vietnam, Vietnamese, chụp 2026-10-14). Vị trí là ảnh chụp một thời điểm, không phải thứ hạng cố định.
A2: Truy vấn | B2: Cụm | C2: Vị trí | D2: Miền | E2: URL | F2: Title | G2: Quan hệ | H2: Tính năng SERP | I2: AI Overview | J2: Miền được AI Overview trích | K2: Công cụ | L2: Thời điểm lấy
A3: app thuê xe máy | B3: K01 | C3: 1 | D3: play.google.com | E3: https://play.google.com/store/apps/details?id=com.skoot.now&hl=vi | F3: Skoot | The Scooter Rental App - Ứng dụng trên Google Play | G3: đối thủ | H3: ai_overview, organic, people_also_ask | I3: Có | J3: Không | K3: openrush | L3: 2026-10-14T14:27:51.537382Z
A4: app thuê xe máy | B4: K01 | C4: 2 | D4: erent.vn | E4: https://erent.vn/app-thue-tai-xe/ | F4: App thuê tài xế E-rent | G4: đối thủ | H4: ai_overview, organic, people_also_ask | I4: Có | J4: Có | K4: openrush | L4: 2026-10-14T14:27:51.537382Z
A5: app thuê xe máy | B5: K01 | C5: 3 | D5: apps.apple.com | E5: https://apps.apple.com/vn/app/%E1%BB%A9ng-d%E1%BB%A5ng-cho-thu%C3%AA-%C3%B4-t%C3%B4-%C4%91%E1%BA%B7t-xe/id1590139268?l=vi | F5: Ứng dụng cho thuê ô tô・đặt xe - App Store - Apple | G5: đối thủ | H5: ai_overview, organic, people_also_ask | I5: Có | J5: Không | K5: openrush | L5: 2026-10-14T14:27:51.537382Z
A6: app thuê xe máy | B6: K01 | C6: 4 | D6: moma.vn | E6: https://moma.vn/tin-tuc/top-7-app-thue-xe-tu-lai-tiet-kiem-den-60-chi-phi-so-voi-thue-xe-truyen-thong-1ZWM2bMb | F6: Top 7 App Thuê Xe Tự Lái: Tiết Kiệm Đến 60% Chi Phí So ... | G6: đối thủ | H6: ai_overview, organic, people_also_ask | I6: Có | J6: Không | K6: openrush | L6: 2026-10-14T14:27:51.537382Z
A7: app thuê xe máy | B7: K01 | C7: 5 | D7: play.google.com | E7: https://play.google.com/store/apps/details?id=com.rentalcars.online&hl=vi | F7: Ứng dụng cho thuê xe・đặt xe | G7: đối thủ | H7: ai_overview, organic, people_also_ask | I7: Có | J7: Không | K7: openrush | L7: 2026-10-14T14:27:51.537382Z
A8: app thuê xe máy | B8: K01 | C8: 6 | D8: giaiphapgiaothong.com | E8: https://giaiphapgiaothong.com/blogs/blogs/top-9-ung-dung-cho-thue-xe-tu-lai-tren-ios-android | F8: Top 9 Ứng Dụng Cho Thuê Xe Tự Lái Trên iOS, Android | G8: đối thủ | H8: ai_overview, organic, people_also_ask | I8: Có | J8: Có | K8: openrush | L8: 2026-10-14T14:27:51.537382Z
A9: app thuê xe máy | B9: K01 | C9: 7 | D9: chatbot.thuexemaynguyentu.com | E9: https://chatbot.thuexemaynguyentu.com/blog/app/app-thue-xe-khong-can-tai-khoan/ | F9: App Thuê xe Không Cần Tài Khoản - MotoAI | G9: website này | H9: ai_overview, organic, people_also_ask | I9: Có | J9: Không | K9: openrush | L9: 2026-10-14T14:27:51.537382Z
A10: app thuê xe máy | B10: K01 | C10: 8 | D10: www.facebook.com | E10: https://www.facebook.com/groups/247616304947433/posts/967020739673649/ | F10: Cõ chỗ nào cho thuê xe để chạy k ạ e có app rồi | G10: đối thủ | H10: ai_overview, organic, people_also_ask | I10: Có | J10: Không | K10: openrush | L10: 2026-10-14T14:27:51.537382Z
A11: app thuê xe máy | B11: K01 | C11: 9 | D11: chatbot.thuexemaynguyentu.com | E11: https://chatbot.thuexemaynguyentu.com/blog/app/cach-dung-ung-dung-thue-xe-may/ | F11: Cách dùng ứng dụng thuê xe máy: 5 bước từ hỏi giá đến ... | G11: website này | H11: ai_overview, organic, people_also_ask | I11: Có | J11: Không | K11: openrush | L11: 2026-10-14T14:27:51.537382Z
A12: app thuê xe máy hà nội | B12: K01 | C12: 1 | D12: play.google.com | E12: https://play.google.com/store/apps/details?id=casuvang.com.motorbikerental | F12: TRAVEL LOOK: THUÊ XE MÁY - Apps on Google Play | G12: đối thủ | H12: ai_overview, organic, related_searches | I12: Có | J12: Không | K12: openseo | L12: 2026-10-14T14:35:56Z
A13: app thuê xe máy hà nội | B13: K01 | C13: 2 | D13: giaiphapgiaothong.com | E13: https://giaiphapgiaothong.com/blogs/blogs/top-4-app-thue-xe-o-to-xe-may-tu-lai-tot-nhat-tren-android-ios | F13: TOP 4 app thuê xe ô tô, xe máy tự lái tốt nhất trên Android, iOS | G13: đối thủ | H13: ai_overview, organic, related_searches | I13: Có | J13: Không | K13: openseo | L13: 2026-10-14T14:35:56Z
A14: app thuê xe máy hà nội | B14: K01 | C14: 3 | D14: www.facebook.com | E14: https://www.facebook.com/groups/855684482804801/posts/1704327764607131/ | F14: Tìm thuê xe và tài khoản app chạy XanhSM tại Hà Nội? | G14: đối thủ | H14: ai_overview, organic, related_searches | I14: Có | J14: Không | K14: openseo | L14: 2026-10-14T14:35:56Z
... A1135: thuê xe máy hà nội | B1135: LANDSCAPE | C1135: 15 | D1135: luhanhvietnam.com.vn | E1135: https://luhanhvietnam.com.vn/du-lich/dia-chi-thue-xe-may-ha-noi-gia-re.html | F1135: Tư vấn địa chỉ thuê xe máy Hà Nội giá rẻ và lưu ý quan trọng | G1135: đối thủ | H1135: ai_overview, local_pack, organic, related_searches | I1135: Có | J1135: Không | K1135: openseo | L1135: 2026-10-14T14:35:21Z

Sheet URL–KEYWORD MAPPING
A1: URL | B1: Article ID | C1: Loại trang | D1: Từ khóa chính | E1: Từ khóa phụ | F1: Ý định | G1: Cụm | H1: Volume/tháng | I1: Nguồn volume | J1: Vị trí quan sát (SERP chụp) | K1: Quan hệ pillar
A2: https://chatbot.thuexemaynguyentu.com/ | B2: N/A | C2: Trang chủ (website) | D2: cho thuê xe máy ở Hà Nội | E2: cho thuê xe máy Hà Nội; thuê xe máy Hà Nội; thuê xe máy ở Hà Nội; trợ lý thuê xe máy | F2: Thương mại / dịch vụ cho thuê | G2: K02 Giá thuê xe máy | H2: N/A | I2: N/A — chưa đo volume | J2: N/A — truy vấn chưa chụp SERP | K2: Không (trang điều hướng/chuyển đổi duy nhất)
A3: https://chatbot.thuexemaynguyentu.com/agent/ | B3: N/A | C3: Ứng dụng Agent (chat) | D3: ứng dụng thuê xe máy | E3: app thuê xe máy; app thuê xe điện; ứng dụng thuê xe máy điện; công cụ tính giá thuê xe máy | F3: Thông tin sản phẩm / công cụ | G3: K01 Ứng dụng & Agent thuê xe máy | H3: 30 | I3: Đo được (keyword-demand / DataForSEO) | J3: không thấy trong top kết quả (2026-10-14) | K3: Không (trang điều hướng/chuyển đổi duy nhất)
A4: https://chatbot.thuexemaynguyentu.com/blog/ | B4: N/A | C4: Blog home | D4: cẩm nang thuê xe máy | E4: kinh nghiệm thuê xe máy; thủ tục thuê xe máy; giá thuê xe máy | F4: Thông tin / điều hướng | G4: Tất cả cụm | H4: N/A | I4: N/A — chưa đo volume | J4: N/A — truy vấn chưa chụp SERP | K4: Không (trang điều hướng/chuyển đổi duy nhất)
A5: https://chatbot.thuexemaynguyentu.com/chinh-sach/ | B5: N/A | C5: Trang chính sách thuê xe | D5: chính sách thuê xe máy | E5: đặt cọc thuê xe máy; giao xe tận nơi; giấy tờ thuê xe | F5: Thông tin - chuyển đổi | G5: K04 Thủ tục, giấy tờ, hợp đồng và đặt cọc | H5: N/A | I5: N/A — chưa đo volume | J5: N/A — truy vấn chưa chụp SERP | K5: Không (trang điều hướng/chuyển đổi duy nhất)
A6: https://chatbot.thuexemaynguyentu.com/doi-tac/ | B6: N/A | C6: Trang đối tác (B2B) | D6: thuê xe máy theo đoàn | E6: thuê xe máy cho công ty du lịch; thuê xe máy cho khách sạn; thuê xe máy cho hướng dẫn viên | F6: Thương mại / đối tác | G6: K19 Kinh nghiệm thuê xe cho khách du lịch | H6: N/A | I6: N/A — chưa đo volume | J6: N/A — truy vấn chưa chụp SERP | K6: Không (trang điều hướng/chuyển đổi duy nhất)
A7: https://chatbot.thuexemaynguyentu.com/gia-thue/ | B7: N/A | C7: Trang chuyển đổi (giá) | D7: giá thuê xe máy Hà Nội | E7: bảng giá thuê xe máy; giá thuê xe máy theo ngày; giá thuê xe máy theo tháng; giá thuê xe tay ga | F7: Thương mại / chuyển đổi | G7: K02 Giá thuê xe máy | H7: N/A | I7: N/A — chưa đo volume | J7: không thấy trong top kết quả (2026-10-14) | K7: Không (trang điều hướng/chuyển đổi duy nhất)
A8: https://chatbot.thuexemaynguyentu.com/gioi-thieu/ | B8: N/A | C8: Trang giới thiệu (E-E-A-T) | D8: giới thiệu thuê xe máy Nguyễn Tú | E8: MotoAI; trợ lý thuê xe máy | F8: Điều hướng / thương hiệu | G8: K01 Ứng dụng & Agent thuê xe máy | H8: N/A | I8: N/A — chưa đo volume | J8: N/A — truy vấn chưa chụp SERP | K8: Không (trang điều hướng/chuyển đổi duy nhất)
A9: https://chatbot.thuexemaynguyentu.com/lien-he/ | B9: N/A | C9: Trang chuyển đổi (liên hệ) | D9: địa chỉ thuê xe máy Nguyễn Tú | E9: liên hệ thuê xe máy Nguyễn Tú; số điện thoại thuê xe máy; địa chỉ thuê xe máy Long Biên | F9: Điều hướng / chuyển đổi | G9: K15 Long Biên – Gia Lâm – Bát Tràng (khu vực cửa hàng) | H9: N/A | I9: N/A — chưa đo volume | J9: N/A — truy vấn chưa chụp SERP | K9: Không (trang điều hướng/chuyển đổi duy nhất)
A10: https://chatbot.thuexemaynguyentu.com/privacy/ | B10: N/A | C10: Pháp lý | D10: chính sách bảo mật MotoAI | E10: N/A | F10: Điều hướng | G10: Tất cả cụm | H10: N/A | I10: N/A — chưa đo volume | J10: N/A — truy vấn chưa chụp SERP | K10: Không (trang điều hướng/chuyển đổi duy nhất)
A11: https://chatbot.thuexemaynguyentu.com/terms/ | B11: N/A | C11: Pháp lý | D11: điều khoản sử dụng MotoAI | E11: N/A | F11: Điều hướng | G11: Tất cả cụm | H11: N/A | I11: N/A — chưa đo volume | J11: N/A — truy vấn chưa chụp SERP | K11: Không (trang điều hướng/chuyển đổi duy nhất)
A12: https://chatbot.thuexemaynguyentu.com/blog/an-toan/ | B12: N/A | C12: Hub danh mục | D12: luật giao thông và an toàn khi thuê xe máy | E12: an toàn / pháp lý | F12: Điều hướng / danh sách | G12: K10 An toàn khi lái xe máy | H12: N/A | I12: N/A — chưa đo volume | J12: N/A — truy vấn chưa chụp SERP | K12: Không (trang điều hướng/chuyển đổi duy nhất)
A13: https://chatbot.thuexemaynguyentu.com/blog/app/ | B13: N/A | C13: Hub danh mục | D13: hướng dẫn dùng ứng dụng thuê xe máy | E13: ứng dụng thuê xe máy | F13: Điều hướng / danh sách | G13: K01 Ứng dụng & Agent thuê xe máy | H13: N/A | I13: N/A — chưa đo volume | J13: N/A — truy vấn chưa chụp SERP | K13: Không (trang điều hướng/chuyển đổi duy nhất)
A14: https://chatbot.thuexemaynguyentu.com/blog/cong-cu-huong-dan/ | B14: N/A | C14: Hub cụm chủ đề | D14: công cụ và hướng dẫn thuê xe máy | E14: N/A | F14: Điều hướng / pillar cụm | G14: Nhiều cụm | H14: N/A | I14: N/A — chưa đo volume | J14: N/A — truy vấn chưa chụp SERP | K14: Không (trang điều hướng/chuyển đổi duy nhất)
A15: https://chatbot.thuexemaynguyentu.com/blog/dia-phuong/ | B15: N/A | C15: Hub danh mục | D15: đi xe máy ở hà nội | E15: địa phương / du lịch | F15: Điều hướng / danh sách | G15: K17 Hành trình ngoại thành và tỉnh lân cận | H15: N/A | I15: N/A — chưa đo volume | J15: N/A — truy vấn chưa chụp SERP | K15: Không (trang điều hướng/chuyển đổi duy nhất)
... A19: https://chatbot.thuexemaynguyentu.com/blog/thue-xe/ | B19: N/A | C19: Hub danh mục | D19: kinh nghiệm thuê xe máy | E19: thuê xe máy | F19: Điều hướng / danh sách | G19: K19 Kinh nghiệm thuê xe cho khách du lịch | H19: N/A | I19: N/A — chưa đo volume | J19: N/A — truy vấn chưa chụp SERP | K19: Không (trang điều hướng/chuyển đổi duy nhất)
A20: https://chatbot.thuexemaynguyentu.com/blog/xe-dien/ | B20: N/A | C20: Hub danh mục | D20: thuê xe máy điện hà nội | E20: xe điện / xe máy điện | F20: Điều hướng / danh sách | G20: K08 Xe máy điện và xe đạp điện | H20: 260 | I20: Đo được (keyword-demand / DataForSEO) | J20: không thấy trong top kết quả (2026-10-14) | K20: Không (trang điều hướng/chuyển đổi duy nhất)
A21: https://chatbot.thuexemaynguyentu.com/blog/an-toan/ai-chiu-phat-khi-di-xe-thue-cho-du-khach/ | B21: BA-0497 | C21: Bài viết | D21: ai chịu phạt khi đi xe thuê cho du khách | E21: ai chịu phạt khi đi xe thuê; bằng lái khi thuê xe máy; pháp luật | F21: Thông tin pháp lý | G21: K09 Bằng lái và luật giao thông | H21: N/A | I21: N/A — chưa đo volume | J21: N/A — truy vấn chưa chụp SERP | K21: Hỗ trợ pillar BA-0215 ("ai chịu phạt khi đi xe thuê")
A22: https://chatbot.thuexemaynguyentu.com/blog/an-toan/ai-chiu-phat-khi-di-xe-thue-cho-nguoi-moi/ | B22: BA-0779 | C22: Bài viết | D22: ai chịu phạt khi đi xe thuê cho người mới | E22: ai chịu phạt khi đi xe thuê; bằng lái khi thuê xe máy; pháp luật | F22: Thông tin pháp lý | G22: K09 Bằng lái và luật giao thông | H22: N/A | I22: N/A — chưa đo volume | J22: N/A — truy vấn chưa chụp SERP | K22: Hỗ trợ pillar BA-0215 ("ai chịu phạt khi đi xe thuê")
A23: https://chatbot.thuexemaynguyentu.com/blog/an-toan/ai-chiu-phat-khi-di-xe-thue-tom-tat/ | B23: BA-1061 | C23: Bài viết | D23: tóm tắt ai chịu phạt khi đi xe thuê | E23: ai chịu phạt khi đi xe thuê; bằng lái khi thuê xe máy; pháp luật | F23: Thông tin pháp lý | G23: K09 Bằng lái và luật giao thông | H23: N/A | I23: N/A — chưa đo volume | J23: N/A — truy vấn chưa chụp SERP | K23: Hỗ trợ pillar BA-0215 ("ai chịu phạt khi đi xe thuê")
A24: https://chatbot.thuexemaynguyentu.com/blog/an-toan/ai-chiu-phat-khi-di-xe-thue-vi-du-thuc-te/ | B24: BA-1343 | C24: Bài viết | D24: ví dụ ai chịu phạt khi đi xe thuê | E24: ai chịu phạt khi đi xe thuê; bằng lái khi thuê xe máy; pháp luật | F24: Thông tin pháp lý | G24: K09 Bằng lái và luật giao thông | H24: N/A | I24: N/A — chưa đo volume | J24: N/A — truy vấn chưa chụp SERP | K24: Hỗ trợ pillar BA-0215 ("ai chịu phạt khi đi xe thuê")
A25: https://chatbot.thuexemaynguyentu.com/blog/an-toan/ai-chiu-phat-khi-di-xe-thue/ | B25: BA-0215 | C25: Bài viết | D25: ai chịu phạt khi đi xe thuê | E25: bằng lái khi thuê xe máy; pháp luật | F25: Thông tin pháp lý | G25: K09 Bằng lái và luật giao thông | H25: N/A | I25: N/A — chưa đo volume | J25: N/A — truy vấn chưa chụp SERP | K25: Pillar cụm "ai chịu phạt khi đi xe thuê" (5 bài)
A26: https://chatbot.thuexemaynguyentu.com/blog/an-toan/an-toan-khi-thanh-toan-coc-cho-du-khach/ | B26: BA-0563 | C26: Bài viết | D26: thanh toán cọc thuê xe an toàn cho du khách | E26: thanh toán cọc thuê xe an toàn; thủ tục thuê xe máy | F26: Thông tin pháp lý | G26: K04 Thủ tục, giấy tờ, hợp đồng và đặt cọc | H26: N/A | I26: N/A — chưa đo volume | J26: N/A — truy vấn chưa chụp SERP | K26: Hỗ trợ pillar BA-0281 ("thanh toán cọc thuê xe an toàn")
A27: https://chatbot.thuexemaynguyentu.com/blog/an-toan/an-toan-khi-thanh-toan-coc-cho-nguoi-moi/ | B27: BA-0845 | C27: Bài viết | D27: thanh toán cọc thuê xe an toàn cho người mới | E27: thanh toán cọc thuê xe an toàn; thủ tục thuê xe máy | F27: Thông tin pháp lý | G27: K04 Thủ tục, giấy tờ, hợp đồng và đặt cọc | H27: N/A | I27: N/A — chưa đo volume | J27: N/A — truy vấn chưa chụp SERP | K27: Hỗ trợ pillar BA-0281 ("thanh toán cọc thuê xe an toàn")
A28: https://chatbot.thuexemaynguyentu.com/blog/an-toan/an-toan-khi-thanh-toan-coc-tom-tat/ | B28: BA-1127 | C28: Bài viết | D28: tóm tắt thanh toán cọc thuê xe an toàn | E28: thanh toán cọc thuê xe an toàn; thủ tục thuê xe máy | F28: Thông tin pháp lý | G28: K04 Thủ tục, giấy tờ, hợp đồng và đặt cọc | H28: N/A | I28: N/A — chưa đo volume | J28: N/A — truy vấn chưa chụp SERP | K28: Hỗ trợ pillar BA-0281 ("thanh toán cọc thuê xe an toàn")
A29: https://chatbot.thuexemaynguyentu.com/blog/an-toan/an-toan-khi-thanh-toan-coc-vi-du-thuc-te/ | B29: BA-1409 | C29: Bài viết | D29: ví dụ thanh toán cọc thuê xe an toàn | E29: thanh toán cọc thuê xe an toàn; thủ tục thuê xe máy | F29: Thông tin pháp lý | G29: K04 Thủ tục, giấy tờ, hợp đồng và đặt cọc | H29: N/A | I29: N/A — chưa đo volume | J29: N/A — truy vấn chưa chụp SERP | K29: Hỗ trợ pillar BA-0281 ("thanh toán cọc thuê xe an toàn")
A30: https://chatbot.thuexemaynguyentu.com/blog/an-toan/an-toan-khi-thanh-toan-coc/ | B30: BA-0281 | C30: Bài viết | D30: thanh toán cọc thuê xe an toàn | E30: thủ tục thuê xe máy | F30: Thông tin pháp lý | G30: K04 Thủ tục, giấy tờ, hợp đồng và đặt cọc | H30: N/A | I30: N/A — chưa đo volume | J30: N/A — truy vấn chưa chụp SERP | K30: Pillar cụm "thanh toán cọc thuê xe an toàn" (5 bài)
A31: https://chatbot.thuexemaynguyentu.com/blog/an-toan/bang-lai-a1-a2-khac-gi-cau-hoi-thuong-gap/ | B31: BA-1445 | C31: Bài viết | D31: câu hỏi thường gặp bằng lái a1 a2 | E31: bằng lái a1 a2 khác gì; bằng lái khi thuê xe máy; bằng lái | F31: Thông tin pháp lý | G31: K09 Bằng lái và luật giao thông | H31: N/A | I31: N/A — chưa đo volume | J31: N/A — truy vấn chưa chụp SERP | K31: Hỗ trợ pillar BA-0035 ("bằng lái a1 a2 khác gì")
A32: https://chatbot.thuexemaynguyentu.com/blog/an-toan/bang-lai-a1-a2-khac-gi-cho-du-khach/ | B32: BA-0317 | C32: Bài viết | D32: bằng lái a1 a2 khác gì cho du khách | E32: bằng lái a1 a2 khác gì; bằng lái khi thuê xe máy; bằng lái | F32: Thông tin pháp lý + so sánh | G32: K09 Bằng lái và luật giao thông | H32: N/A | I32: N/A — chưa đo volume | J32: N/A — truy vấn chưa chụp SERP | K32: Hỗ trợ pillar BA-0035 ("bằng lái a1 a2 khác gì")
... A53: https://chatbot.thuexemaynguyentu.com/blog/an-toan/bao-ve-du-lieu-ca-nhan-khi-thue-xe/ | B53: BA-0275 | C53: Bài viết | D53: bảo vệ dữ liệu cá nhân khi thuê xe | E53: bảo hiểm khi thuê xe máy | F53: Thông tin pháp lý | G53: K11 Bảo hiểm, tai nạn, quyền lợi người thuê | H53: N/A | I53: N/A — chưa đo volume | J53: N/A — truy vấn chưa chụp SERP | K53: Pillar cụm "bảo vệ dữ liệu cá nhân khi thuê xe" (5 bài)
A54: https://chatbot.thuexemaynguyentu.com/blog/an-toan/cac-loai-bang-lai-xe-may/ | B54: BA-2002 | C54: Bài viết | D54: các loại bằng lái xe máy | E54: bằng lái khi thuê xe máy; lái xe | F54: Thông tin pháp lý | G54: K09 Bằng lái và luật giao thông | H54: 1000 | I54: Đo được (keyword-demand / DataForSEO) | J54: không thấy trong top kết quả (2026-10-14) | K54: Pillar cụm "các loại bằng lái xe máy" (1 bài)
A55: https://chatbot.thuexemaynguyentu.com/blog/an-toan/cam-do-xe-may-dung-luat-cho-du-khach/ | B55: BA-0503 | C55: Bài viết | D55: cầm đồ xe máy đúng luật cho du khách | E55: cầm đồ xe máy đúng luật; bằng lái khi thuê xe máy; pháp luật | F55: Thông tin pháp lý | G55: K09 Bằng lái và luật giao thông | H55: N/A | I55: N/A — chưa đo volume | J55: N/A — truy vấn chưa chụp SERP | K55: Hỗ trợ pillar BA-0221 ("cầm đồ xe máy đúng luật")
A56: https://chatbot.thuexemaynguyentu.com/blog/an-toan/cam-do-xe-may-dung-luat-cho-nguoi-moi/ | B56: BA-0785 | C56: Bài viết | D56: cầm đồ xe máy đúng luật cho người mới | E56: cầm đồ xe máy đúng luật; bằng lái khi thuê xe máy; pháp luật | F56: Thông tin pháp lý | G56: K09 Bằng lái và luật giao thông | H56: N/A | I56: N/A — chưa đo volume | J56: N/A — truy vấn chưa chụp SERP | K56: Hỗ trợ pillar BA-0221 ("cầm đồ xe máy đúng luật")
A57: https://chatbot.thuexemaynguyentu.com/blog/an-toan/cam-do-xe-may-dung-luat-tom-tat/ | B57: BA-1067 | C57: Bài viết | D57: tóm tắt cầm đồ xe máy đúng luật | E57: cầm đồ xe máy đúng luật; bằng lái khi thuê xe máy; pháp luật | F57: Thông tin pháp lý | G57: K09 Bằng lái và luật giao thông | H57: N/A | I57: N/A — chưa đo volume | J57: N/A — truy vấn chưa chụp SERP | K57: Hỗ trợ pillar BA-0221 ("cầm đồ xe máy đúng luật")
A58: https://chatbot.thuexemaynguyentu.com/blog/an-toan/cam-do-xe-may-dung-luat-vi-du-thuc-te/ | B58: BA-1349 | C58: Bài viết | D58: ví dụ cầm đồ xe máy đúng luật | E58: cầm đồ xe máy đúng luật; bằng lái khi thuê xe máy; pháp luật | F58: Thông tin pháp lý | G58: K09 Bằng lái và luật giao thông | H58: N/A | I58: N/A — chưa đo volume | J58: N/A — truy vấn chưa chụp SERP | K58: Hỗ trợ pillar BA-0221 ("cầm đồ xe máy đúng luật")
A59: https://chatbot.thuexemaynguyentu.com/blog/an-toan/cam-do-xe-may-dung-luat/ | B59: BA-0221 | C59: Bài viết | D59: cầm đồ xe máy đúng luật | E59: bằng lái khi thuê xe máy; pháp luật | F59: Thông tin pháp lý | G59: K09 Bằng lái và luật giao thông | H59: N/A | I59: N/A — chưa đo volume | J59: N/A — truy vấn chưa chụp SERP | K59: Pillar cụm "cầm đồ xe máy đúng luật" (5 bài)
A60: https://chatbot.thuexemaynguyentu.com/blog/an-toan/cam-xe-may-xang-vanh-dai-1/ | B60: BA-2004 | C60: Bài viết | D60: cấm xe máy xăng vành đai 1 | E60: xe thuê bị hỏng phải làm sao; pháp luật | F60: Thông tin pháp lý | G60: K20 Bảo dưỡng, sự cố và xử lý khi đi đường | H60: N/A | I60: N/A — chưa đo volume | J60: không thấy trong top kết quả (2026-10-14) | K60: Pillar cụm "cấm xe máy xăng vành đai 1" (1 bài)
A61: https://chatbot.thuexemaynguyentu.com/blog/an-toan/camera-phat-nguoi-khi-thue-xe-cho-du-khach/ | B61: BA-0485 | C61: Bài viết | D61: camera phạt nguội khi thuê xe cho du khách | E61: camera phạt nguội khi thuê xe; bằng lái khi thuê xe máy; pháp luật | F61: Thông tin pháp lý | G61: K09 Bằng lái và luật giao thông | H61: N/A | I61: N/A — chưa đo volume | J61: N/A — truy vấn chưa chụp SERP | K61: Hỗ trợ pillar BA-0203 ("camera phạt nguội khi thuê xe")
A62: https://chatbot.thuexemaynguyentu.com/blog/an-toan/camera-phat-nguoi-khi-thue-xe-cho-nguoi-moi/ | B62: BA-0767 | C62: Bài viết | D62: camera phạt nguội khi thuê xe cho người mới | E62: camera phạt nguội khi thuê xe; bằng lái khi thuê xe máy; pháp luật | F62: Thông tin pháp lý | G62: K09 Bằng lái và luật giao thông | H62: N/A | I62: N/A — chưa đo volume | J62: N/A — truy vấn chưa chụp SERP | K62: Hỗ trợ pillar BA-0203 ("camera phạt nguội khi thuê xe")
A63: https://chatbot.thuexemaynguyentu.com/blog/an-toan/camera-phat-nguoi-khi-thue-xe-tom-tat/ | B63: BA-1049 | C63: Bài viết | D63: tóm tắt camera phạt nguội khi thuê xe | E63: camera phạt nguội khi thuê xe; bằng lái khi thuê xe máy; pháp luật | F63: Thông tin pháp lý | G63: K09 Bằng lái và luật giao thông | H63: N/A | I63: N/A — chưa đo volume | J63: N/A — truy vấn chưa chụp SERP | K63: Hỗ trợ pillar BA-0203 ("camera phạt nguội khi thuê xe")
...

Sheet CANNIBALIZATION
A1: Quy tắc: không gộp chỉ vì từ khóa giống nhau. Gộp/redirect cần (1) trùng ý định + (2) trùng nội dung (Jaccard ≥ 0,5) hoặc (3) GSC cho thấy URL hoán đổi — N/A — thiếu nguồn: Google Search Console chưa kết nối (OpenSEO 0 tài khoản Google; data/seo/performance/ trống). Bổ ngữ slug nhận diện: cho-khach-nuoc-ngoai, cau-hoi-thuong-gap, cho-khach-du-lich, hai-ngay-mot-dem, cho-nguoi-moi, cho-sinh-vien, vi-du-thuc-te, cho-du-khach, cho-gia-dinh, gia-tot-nhat, ky-nghi-le, tai-ha-noi, trong-ngay, cuoi-tuan, nhanh-gon, buoi-sang, checklist, nam-2026, buoi-toi, chay-pho, gia-tot, tom-tat, mua-thu, tan-noi, dai-han, mua-mua, mua-he.
A2: Loại kiểm tra | B2: Từ khóa / chủ đề | C2: Số URL | D2: URL | E2: Jaccard cao nhất | F2: Tỉ lệ nội dung riêng thấp nhất | G2: Kết luận | H2: Bằng chứng
A3: Hub kế thừa từ khóa danh mục (báo cáo seo-master-audit) | B3: hướng dẫn dùng ứng dụng thuê xe máy | C3: 8 | D3: https://chatbot.thuexemaynguyentu.com/blog/app/ | https://chatbot.thuexemaynguyentu.com/blog/app/dat-xe/ | https://chatbot.thuexemaynguyentu.com/blog/app/huong-dan/ | https://chatbot.thuexemaynguyentu.com/blog/app/so-sanh/ | https://chatbot.thuexemaynguyentu.com/blog/app/tim-xe/ | https://chatbot.thuexemaynguyentu.com/blog/app/tinh-gia/ | https://chatbot.thuexemaynguyentu.com/blog/app/tro-ly/ | https://chatbot.thuexemaynguyentu.com/blog/app/web-app/ | E3: N/A | F3: N/A | G3: WATCH | H3: 8 hub (title/H1 khác nhau) + 16 trang phân trang dùng chung từ khóa danh mục trong báo cáo; trang phân trang tự canonical là chuỗi hợp lệ. Việc: gán từ khóa riêng cho hub chủ đề con trong seo-master-audit (P3), không gộp/redirect
